{
 "cells": [
  {
   "cell_type": "code",
   "execution_count": 2,
   "metadata": {},
   "outputs": [],
   "source": [
    "from osgeo import gdal, ogr"
   ]
  },
  {
   "cell_type": "code",
   "execution_count": 11,
   "metadata": {},
   "outputs": [
    {
     "data": {
      "text/plain": [
       "osgeo.gdal.Dataset"
      ]
     },
     "execution_count": 11,
     "metadata": {},
     "output_type": "execute_result"
    }
   ],
   "source": [
    "input_raster = gdal.Open(r\"data\\original\\bathymetry_hawaii.tif\")\n",
    "type(input_raster)"
   ]
  },
  {
   "cell_type": "code",
   "execution_count": 13,
   "metadata": {},
   "outputs": [
    {
     "data": {
      "text/plain": [
       "'GEOGCS[\"WGS 84\",DATUM[\"WGS_1984\",SPHEROID[\"WGS 84\",6378137,298.257223563,AUTHORITY[\"EPSG\",\"7030\"]],AUTHORITY[\"EPSG\",\"6326\"]],PRIMEM[\"Greenwich\",0],UNIT[\"degree\",0.0174532925199433,AUTHORITY[\"EPSG\",\"9122\"]],AXIS[\"Latitude\",NORTH],AXIS[\"Longitude\",EAST],AUTHORITY[\"EPSG\",\"4326\"]]'"
      ]
     },
     "execution_count": 13,
     "metadata": {},
     "output_type": "execute_result"
    }
   ],
   "source": [
    "# Projection\n",
    "input_raster.GetProjection()"
   ]
  },
  {
   "cell_type": "code",
   "execution_count": 14,
   "metadata": {},
   "outputs": [
    {
     "data": {
      "text/plain": [
       "2312"
      ]
     },
     "execution_count": 14,
     "metadata": {},
     "output_type": "execute_result"
    }
   ],
   "source": [
    "# Dimensions\n",
    "input_raster.RasterXSize\n",
    "input_raster.RasterYSize"
   ]
  },
  {
   "cell_type": "code",
   "execution_count": 15,
   "metadata": {},
   "outputs": [
    {
     "data": {
      "text/plain": [
       "1"
      ]
     },
     "execution_count": 15,
     "metadata": {},
     "output_type": "execute_result"
    }
   ],
   "source": [
    "# Number of bands\n",
    "input_raster.RasterCount"
   ]
  },
  {
   "cell_type": "code",
   "execution_count": 16,
   "metadata": {},
   "outputs": [
    {
     "data": {
      "text/plain": [
       "{'AREA_OR_POINT': 'Area',\n",
       " 'elevation#grid_mapping': 'crs',\n",
       " 'elevation#long_name': 'Elevation relative to sea level',\n",
       " 'elevation#sdn_parameter_name': 'Sea floor height (above mean sea level) {bathymetric height}',\n",
       " 'elevation#sdn_parameter_urn': 'SDN:P01::ALATZZ01',\n",
       " 'elevation#sdn_uom_name': 'Metres',\n",
       " 'elevation#sdn_uom_urn': 'SDN:P06::ULAA',\n",
       " 'elevation#standard_name': 'height_above_mean_sea_level',\n",
       " 'elevation#units': 'm',\n",
       " 'lat#axis': 'Y',\n",
       " 'lat#long_name': 'latitude',\n",
       " 'lat#sdn_parameter_name': 'Latitude north',\n",
       " 'lat#sdn_parameter_urn': 'SDN:P01::ALATZZ01',\n",
       " 'lat#sdn_uom_name': 'Degrees north',\n",
       " 'lat#sdn_uom_urn': 'SDN:P06::DEGN',\n",
       " 'lat#standard_name': 'latitude',\n",
       " 'lat#units': 'degrees_north',\n",
       " 'lon#axis': 'X',\n",
       " 'lon#long_name': 'longitude',\n",
       " 'lon#sdn_parameter_name': 'Longitude east',\n",
       " 'lon#sdn_parameter_urn': 'SDN:P01::ALONZZ01',\n",
       " 'lon#sdn_uom_name': 'Degrees east',\n",
       " 'lon#sdn_uom_urn': 'SDN:P06::DEGE',\n",
       " 'lon#standard_name': 'longitude',\n",
       " 'lon#units': 'degrees_east',\n",
       " 'NC_GLOBAL#comment': 'The data in the GEBCO_2021 Grid should not be used for navigation or any purpose relating to safety at sea.',\n",
       " 'NC_GLOBAL#Conventions': 'CF-1.6, ACDD-1.3',\n",
       " 'NC_GLOBAL#creator_email': 'gdacc@seabed2030.org',\n",
       " 'NC_GLOBAL#creator_name': 'GEBCO through the Nippon Foundation-GEBCO Seabed 2030 Project',\n",
       " 'NC_GLOBAL#creator_type': 'International organisation',\n",
       " 'NC_GLOBAL#creator_url': 'https://www.gebco.net',\n",
       " 'NC_GLOBAL#date_created': '2021-07-01',\n",
       " 'NC_GLOBAL#geospatial_bounds': '{-180,-90,180,90}',\n",
       " 'NC_GLOBAL#geospatial_bounds_crs': 'WGS84',\n",
       " 'NC_GLOBAL#geospatial_bounds_vertical_crs': 'EPSG:5831',\n",
       " 'NC_GLOBAL#geospatial_lat_max': '90',\n",
       " 'NC_GLOBAL#geospatial_lat_min': '-90',\n",
       " 'NC_GLOBAL#geospatial_lat_resolution': '0.004166666666666667',\n",
       " 'NC_GLOBAL#geospatial_lat_units': 'degrees_north',\n",
       " 'NC_GLOBAL#geospatial_lon_max': '180',\n",
       " 'NC_GLOBAL#geospatial_lon_min': '-180',\n",
       " 'NC_GLOBAL#geospatial_lon_resolution': '0.004166666666666667',\n",
       " 'NC_GLOBAL#geospatial_lon_units': 'degrees_east',\n",
       " 'NC_GLOBAL#geospatial_vertical_max': '8685',\n",
       " 'NC_GLOBAL#geospatial_vertical_min': '-10977',\n",
       " 'NC_GLOBAL#geospatial_vertical_positive': 'up',\n",
       " 'NC_GLOBAL#geospatial_vertical_resolution': '1',\n",
       " 'NC_GLOBAL#geospatial_vertical_units': 'meters',\n",
       " 'NC_GLOBAL#history': 'Information on the development of the data set and the source data sets included in the grid can be found in the data set documentation available from https://www.gebco.net',\n",
       " 'NC_GLOBAL#id': 'DOI: 10.5285/c6612cbe-50b3-0cff-e053-6c86abc09f8f',\n",
       " 'NC_GLOBAL#identifier_product_doi': 'DOI: 10.5285/c6612cbe-50b3-0cff-e053-6c86abc09f8f',\n",
       " 'NC_GLOBAL#institution': 'On behalf of the General Bathymetric Chart of the Oceans (GEBCO), the data are held at the British Oceanographic Data Centre (BODC).',\n",
       " 'NC_GLOBAL#keywords': 'BATHYMETRY/SEAFLOOR TOPOGRAPHY, DIGITAL ELEVATION/DIGITAL TERRAIN MODELS',\n",
       " 'NC_GLOBAL#license': 'The GEBCO Grid is placed in the public domain and may be used free of charge. Use of the GEBCO Grid indicates that the user accepts the conditions of use and disclaimer information: https://www.gebco.net/data_and_products/gridded_bathymetry_data/gebco_2019/grid_terms_of_use.html',\n",
       " 'NC_GLOBAL#naming_authority': 'https://dx.doi.org',\n",
       " 'NC_GLOBAL#node_offset': '1',\n",
       " 'NC_GLOBAL#project': 'Nippon Foundation - GEBCO Seabed2030 Project',\n",
       " 'NC_GLOBAL#references': 'DOI: 10.5285/c6612cbe-50b3-0cff-e053-6c86abc09f8f',\n",
       " 'NC_GLOBAL#source': 'The GEBCO_2021 Grid is the latest global bathymetric product released by the General Bathymetric Chart of the Oceans (GEBCO) and has been developed through the Nippon Foundation-GEBCO Seabed 2030 Project. This is a collaborative project between the Nippon Foundation of Japan and GEBCO. The Seabed 2030 Project aims to bring together all available bathymetric data to produce the definitive map of the world ocean floor and make it available to all.',\n",
       " 'NC_GLOBAL#summary': \"The GEBCO_2021 Grid is a continuous, global terrain model for ocean and land with a spatial resolution of 15 arc seconds.The grid uses as a 'base-map' Version 2.2 of the SRTM15+ data set (Tozer et al, 2019). This data set is a fusion of land topography with measured and estimated seafloor topography. It is augmented with gridded bathymetric data sets developed as part of the Nippon Foundation-GEBCO Seabed 2030 Project.\",\n",
       " 'NC_GLOBAL#title': 'The GEBCO_2021 Grid - a continuous terrain model for oceans and land at 15 arc-second intervals'}"
      ]
     },
     "execution_count": 16,
     "metadata": {},
     "output_type": "execute_result"
    }
   ],
   "source": [
    "# Metadata for the raster dataset\n",
    "input_raster.GetMetadata()"
   ]
  },
  {
   "cell_type": "markdown",
   "metadata": {},
   "source": [
    "## Shapefile"
   ]
  },
  {
   "cell_type": "code",
   "execution_count": 18,
   "metadata": {},
   "outputs": [
    {
     "ename": "UnicodeDecodeError",
     "evalue": "'utf-8' codec can't decode byte 0xe3 in position 76: invalid continuation byte",
     "output_type": "error",
     "traceback": [
      "\u001b[1;31m---------------------------------------------------------------------------\u001b[0m",
      "\u001b[1;31mUnicodeDecodeError\u001b[0m                        Traceback (most recent call last)",
      "\u001b[1;31mUnicodeDecodeError\u001b[0m: 'utf-8' codec can't decode byte 0xe3 in position 76: invalid continuation byte"
     ]
    },
    {
     "name": "stderr",
     "output_type": "stream",
     "text": [
      "Exception ignored in: 'fiona._env.log_error'\n",
      "Traceback (most recent call last):\n",
      "  File \"D:\\Programas\\anaconda3\\envs\\gps_project\\lib\\site-packages\\fiona\\env.py\", line 289, in defenv\n",
      "    local._env.start()\n",
      "UnicodeDecodeError: 'utf-8' codec can't decode byte 0xe3 in position 76: invalid continuation byte\n"
     ]
    },
    {
     "ename": "UnicodeDecodeError",
     "evalue": "'utf-8' codec can't decode byte 0xe3 in position 76: invalid continuation byte",
     "output_type": "error",
     "traceback": [
      "\u001b[1;31m---------------------------------------------------------------------------\u001b[0m",
      "\u001b[1;31mUnicodeDecodeError\u001b[0m                        Traceback (most recent call last)",
      "\u001b[1;31mUnicodeDecodeError\u001b[0m: 'utf-8' codec can't decode byte 0xe3 in position 76: invalid continuation byte"
     ]
    },
    {
     "name": "stderr",
     "output_type": "stream",
     "text": [
      "Exception ignored in: 'fiona._env.log_error'\n",
      "Traceback (most recent call last):\n",
      "  File \"D:\\Programas\\anaconda3\\envs\\gps_project\\lib\\site-packages\\fiona\\env.py\", line 289, in defenv\n",
      "    local._env.start()\n",
      "UnicodeDecodeError: 'utf-8' codec can't decode byte 0xe3 in position 76: invalid continuation byte\n"
     ]
    },
    {
     "ename": "UnicodeDecodeError",
     "evalue": "'utf-8' codec can't decode byte 0xe3 in position 81: invalid continuation byte",
     "output_type": "error",
     "traceback": [
      "\u001b[1;31m---------------------------------------------------------------------------\u001b[0m",
      "\u001b[1;31mUnicodeDecodeError\u001b[0m                        Traceback (most recent call last)",
      "\u001b[1;31mUnicodeDecodeError\u001b[0m: 'utf-8' codec can't decode byte 0xe3 in position 81: invalid continuation byte"
     ]
    },
    {
     "name": "stderr",
     "output_type": "stream",
     "text": [
      "Exception ignored in: 'fiona._env.log_error'\n",
      "Traceback (most recent call last):\n",
      "  File \"D:\\Programas\\anaconda3\\envs\\gps_project\\lib\\site-packages\\fiona\\env.py\", line 289, in defenv\n",
      "    local._env.start()\n",
      "UnicodeDecodeError: 'utf-8' codec can't decode byte 0xe3 in position 81: invalid continuation byte\n"
     ]
    },
    {
     "ename": "UnicodeDecodeError",
     "evalue": "'utf-8' codec can't decode byte 0xe3 in position 81: invalid continuation byte",
     "output_type": "error",
     "traceback": [
      "\u001b[1;31m---------------------------------------------------------------------------\u001b[0m",
      "\u001b[1;31mUnicodeDecodeError\u001b[0m                        Traceback (most recent call last)",
      "\u001b[1;31mUnicodeDecodeError\u001b[0m: 'utf-8' codec can't decode byte 0xe3 in position 81: invalid continuation byte"
     ]
    },
    {
     "name": "stderr",
     "output_type": "stream",
     "text": [
      "Exception ignored in: 'fiona._env.log_error'\n",
      "Traceback (most recent call last):\n",
      "  File \"D:\\Programas\\anaconda3\\envs\\gps_project\\lib\\site-packages\\fiona\\env.py\", line 289, in defenv\n",
      "    local._env.start()\n",
      "UnicodeDecodeError: 'utf-8' codec can't decode byte 0xe3 in position 81: invalid continuation byte\n"
     ]
    },
    {
     "ename": "UnicodeDecodeError",
     "evalue": "'utf-8' codec can't decode byte 0xe3 in position 72: invalid continuation byte",
     "output_type": "error",
     "traceback": [
      "\u001b[1;31m---------------------------------------------------------------------------\u001b[0m",
      "\u001b[1;31mUnicodeDecodeError\u001b[0m                        Traceback (most recent call last)",
      "\u001b[1;31mUnicodeDecodeError\u001b[0m: 'utf-8' codec can't decode byte 0xe3 in position 72: invalid continuation byte"
     ]
    },
    {
     "name": "stderr",
     "output_type": "stream",
     "text": [
      "Exception ignored in: 'fiona._env.log_error'\n",
      "Traceback (most recent call last):\n",
      "  File \"D:\\Programas\\anaconda3\\envs\\gps_project\\lib\\site-packages\\fiona\\env.py\", line 289, in defenv\n",
      "    local._env.start()\n",
      "UnicodeDecodeError: 'utf-8' codec can't decode byte 0xe3 in position 72: invalid continuation byte\n"
     ]
    },
    {
     "ename": "UnicodeDecodeError",
     "evalue": "'utf-8' codec can't decode byte 0xe3 in position 72: invalid continuation byte",
     "output_type": "error",
     "traceback": [
      "\u001b[1;31m---------------------------------------------------------------------------\u001b[0m",
      "\u001b[1;31mUnicodeDecodeError\u001b[0m                        Traceback (most recent call last)",
      "\u001b[1;31mUnicodeDecodeError\u001b[0m: 'utf-8' codec can't decode byte 0xe3 in position 72: invalid continuation byte"
     ]
    },
    {
     "name": "stderr",
     "output_type": "stream",
     "text": [
      "Exception ignored in: 'fiona._env.log_error'\n",
      "Traceback (most recent call last):\n",
      "  File \"D:\\Programas\\anaconda3\\envs\\gps_project\\lib\\site-packages\\fiona\\env.py\", line 289, in defenv\n",
      "    local._env.start()\n",
      "UnicodeDecodeError: 'utf-8' codec can't decode byte 0xe3 in position 72: invalid continuation byte\n"
     ]
    },
    {
     "ename": "UnicodeDecodeError",
     "evalue": "'utf-8' codec can't decode byte 0xe3 in position 71: invalid continuation byte",
     "output_type": "error",
     "traceback": [
      "\u001b[1;31m---------------------------------------------------------------------------\u001b[0m",
      "\u001b[1;31mUnicodeDecodeError\u001b[0m                        Traceback (most recent call last)",
      "\u001b[1;31mUnicodeDecodeError\u001b[0m: 'utf-8' codec can't decode byte 0xe3 in position 71: invalid continuation byte"
     ]
    },
    {
     "name": "stderr",
     "output_type": "stream",
     "text": [
      "Exception ignored in: 'fiona._env.log_error'\n",
      "Traceback (most recent call last):\n",
      "  File \"D:\\Programas\\anaconda3\\envs\\gps_project\\lib\\site-packages\\fiona\\env.py\", line 289, in defenv\n",
      "    local._env.start()\n",
      "UnicodeDecodeError: 'utf-8' codec can't decode byte 0xe3 in position 71: invalid continuation byte\n"
     ]
    },
    {
     "ename": "UnicodeDecodeError",
     "evalue": "'utf-8' codec can't decode byte 0xe3 in position 71: invalid continuation byte",
     "output_type": "error",
     "traceback": [
      "\u001b[1;31m---------------------------------------------------------------------------\u001b[0m",
      "\u001b[1;31mUnicodeDecodeError\u001b[0m                        Traceback (most recent call last)",
      "\u001b[1;31mUnicodeDecodeError\u001b[0m: 'utf-8' codec can't decode byte 0xe3 in position 71: invalid continuation byte"
     ]
    },
    {
     "name": "stderr",
     "output_type": "stream",
     "text": [
      "Exception ignored in: 'fiona._env.log_error'\n",
      "Traceback (most recent call last):\n",
      "  File \"D:\\Programas\\anaconda3\\envs\\gps_project\\lib\\site-packages\\fiona\\env.py\", line 289, in defenv\n",
      "    local._env.start()\n",
      "UnicodeDecodeError: 'utf-8' codec can't decode byte 0xe3 in position 71: invalid continuation byte\n"
     ]
    },
    {
     "ename": "UnicodeDecodeError",
     "evalue": "'utf-8' codec can't decode byte 0xe3 in position 76: invalid continuation byte",
     "output_type": "error",
     "traceback": [
      "\u001b[1;31m---------------------------------------------------------------------------\u001b[0m",
      "\u001b[1;31mUnicodeDecodeError\u001b[0m                        Traceback (most recent call last)",
      "\u001b[1;31mUnicodeDecodeError\u001b[0m: 'utf-8' codec can't decode byte 0xe3 in position 76: invalid continuation byte"
     ]
    },
    {
     "name": "stderr",
     "output_type": "stream",
     "text": [
      "Exception ignored in: 'fiona._env.log_error'\n",
      "Traceback (most recent call last):\n",
      "  File \"D:\\Programas\\anaconda3\\envs\\gps_project\\lib\\site-packages\\fiona\\env.py\", line 289, in defenv\n",
      "    local._env.start()\n",
      "UnicodeDecodeError: 'utf-8' codec can't decode byte 0xe3 in position 76: invalid continuation byte\n"
     ]
    },
    {
     "ename": "UnicodeDecodeError",
     "evalue": "'utf-8' codec can't decode byte 0xe3 in position 76: invalid continuation byte",
     "output_type": "error",
     "traceback": [
      "\u001b[1;31m---------------------------------------------------------------------------\u001b[0m",
      "\u001b[1;31mUnicodeDecodeError\u001b[0m                        Traceback (most recent call last)",
      "\u001b[1;31mUnicodeDecodeError\u001b[0m: 'utf-8' codec can't decode byte 0xe3 in position 76: invalid continuation byte"
     ]
    },
    {
     "name": "stderr",
     "output_type": "stream",
     "text": [
      "Exception ignored in: 'fiona._env.log_error'\n",
      "Traceback (most recent call last):\n",
      "  File \"D:\\Programas\\anaconda3\\envs\\gps_project\\lib\\site-packages\\fiona\\env.py\", line 289, in defenv\n",
      "    local._env.start()\n",
      "UnicodeDecodeError: 'utf-8' codec can't decode byte 0xe3 in position 76: invalid continuation byte\n"
     ]
    },
    {
     "ename": "UnicodeDecodeError",
     "evalue": "'utf-8' codec can't decode byte 0xe3 in position 81: invalid continuation byte",
     "output_type": "error",
     "traceback": [
      "\u001b[1;31m---------------------------------------------------------------------------\u001b[0m",
      "\u001b[1;31mUnicodeDecodeError\u001b[0m                        Traceback (most recent call last)",
      "\u001b[1;31mUnicodeDecodeError\u001b[0m: 'utf-8' codec can't decode byte 0xe3 in position 81: invalid continuation byte"
     ]
    },
    {
     "name": "stderr",
     "output_type": "stream",
     "text": [
      "Exception ignored in: 'fiona._env.log_error'\n",
      "Traceback (most recent call last):\n",
      "  File \"D:\\Programas\\anaconda3\\envs\\gps_project\\lib\\site-packages\\fiona\\env.py\", line 289, in defenv\n",
      "    local._env.start()\n",
      "UnicodeDecodeError: 'utf-8' codec can't decode byte 0xe3 in position 81: invalid continuation byte\n"
     ]
    },
    {
     "ename": "UnicodeDecodeError",
     "evalue": "'utf-8' codec can't decode byte 0xe3 in position 81: invalid continuation byte",
     "output_type": "error",
     "traceback": [
      "\u001b[1;31m---------------------------------------------------------------------------\u001b[0m",
      "\u001b[1;31mUnicodeDecodeError\u001b[0m                        Traceback (most recent call last)",
      "\u001b[1;31mUnicodeDecodeError\u001b[0m: 'utf-8' codec can't decode byte 0xe3 in position 81: invalid continuation byte"
     ]
    },
    {
     "name": "stderr",
     "output_type": "stream",
     "text": [
      "Exception ignored in: 'fiona._env.log_error'\n",
      "Traceback (most recent call last):\n",
      "  File \"D:\\Programas\\anaconda3\\envs\\gps_project\\lib\\site-packages\\fiona\\env.py\", line 289, in defenv\n",
      "    local._env.start()\n",
      "UnicodeDecodeError: 'utf-8' codec can't decode byte 0xe3 in position 81: invalid continuation byte\n"
     ]
    },
    {
     "ename": "UnicodeDecodeError",
     "evalue": "'utf-8' codec can't decode byte 0xe3 in position 72: invalid continuation byte",
     "output_type": "error",
     "traceback": [
      "\u001b[1;31m---------------------------------------------------------------------------\u001b[0m",
      "\u001b[1;31mUnicodeDecodeError\u001b[0m                        Traceback (most recent call last)",
      "\u001b[1;31mUnicodeDecodeError\u001b[0m: 'utf-8' codec can't decode byte 0xe3 in position 72: invalid continuation byte"
     ]
    },
    {
     "name": "stderr",
     "output_type": "stream",
     "text": [
      "Exception ignored in: 'fiona._env.log_error'\n",
      "Traceback (most recent call last):\n",
      "  File \"D:\\Programas\\anaconda3\\envs\\gps_project\\lib\\site-packages\\fiona\\env.py\", line 289, in defenv\n",
      "    local._env.start()\n",
      "UnicodeDecodeError: 'utf-8' codec can't decode byte 0xe3 in position 72: invalid continuation byte\n"
     ]
    },
    {
     "ename": "UnicodeDecodeError",
     "evalue": "'utf-8' codec can't decode byte 0xe3 in position 72: invalid continuation byte",
     "output_type": "error",
     "traceback": [
      "\u001b[1;31m---------------------------------------------------------------------------\u001b[0m",
      "\u001b[1;31mUnicodeDecodeError\u001b[0m                        Traceback (most recent call last)",
      "\u001b[1;31mUnicodeDecodeError\u001b[0m: 'utf-8' codec can't decode byte 0xe3 in position 72: invalid continuation byte"
     ]
    },
    {
     "name": "stderr",
     "output_type": "stream",
     "text": [
      "Exception ignored in: 'fiona._env.log_error'\n",
      "Traceback (most recent call last):\n",
      "  File \"D:\\Programas\\anaconda3\\envs\\gps_project\\lib\\site-packages\\fiona\\env.py\", line 289, in defenv\n",
      "    local._env.start()\n",
      "UnicodeDecodeError: 'utf-8' codec can't decode byte 0xe3 in position 72: invalid continuation byte\n"
     ]
    },
    {
     "ename": "UnicodeDecodeError",
     "evalue": "'utf-8' codec can't decode byte 0xe3 in position 71: invalid continuation byte",
     "output_type": "error",
     "traceback": [
      "\u001b[1;31m---------------------------------------------------------------------------\u001b[0m",
      "\u001b[1;31mUnicodeDecodeError\u001b[0m                        Traceback (most recent call last)",
      "\u001b[1;31mUnicodeDecodeError\u001b[0m: 'utf-8' codec can't decode byte 0xe3 in position 71: invalid continuation byte"
     ]
    },
    {
     "name": "stderr",
     "output_type": "stream",
     "text": [
      "Exception ignored in: 'fiona._env.log_error'\n",
      "Traceback (most recent call last):\n",
      "  File \"D:\\Programas\\anaconda3\\envs\\gps_project\\lib\\site-packages\\fiona\\env.py\", line 289, in defenv\n",
      "    local._env.start()\n",
      "UnicodeDecodeError: 'utf-8' codec can't decode byte 0xe3 in position 71: invalid continuation byte\n"
     ]
    },
    {
     "ename": "UnicodeDecodeError",
     "evalue": "'utf-8' codec can't decode byte 0xe3 in position 71: invalid continuation byte",
     "output_type": "error",
     "traceback": [
      "\u001b[1;31m---------------------------------------------------------------------------\u001b[0m",
      "\u001b[1;31mUnicodeDecodeError\u001b[0m                        Traceback (most recent call last)",
      "\u001b[1;31mUnicodeDecodeError\u001b[0m: 'utf-8' codec can't decode byte 0xe3 in position 71: invalid continuation byte"
     ]
    },
    {
     "name": "stderr",
     "output_type": "stream",
     "text": [
      "Exception ignored in: 'fiona._env.log_error'\n",
      "Traceback (most recent call last):\n",
      "  File \"D:\\Programas\\anaconda3\\envs\\gps_project\\lib\\site-packages\\fiona\\env.py\", line 289, in defenv\n",
      "    local._env.start()\n",
      "UnicodeDecodeError: 'utf-8' codec can't decode byte 0xe3 in position 71: invalid continuation byte\n"
     ]
    },
    {
     "ename": "UnicodeDecodeError",
     "evalue": "'utf-8' codec can't decode byte 0xe3 in position 76: invalid continuation byte",
     "output_type": "error",
     "traceback": [
      "\u001b[1;31m---------------------------------------------------------------------------\u001b[0m",
      "\u001b[1;31mUnicodeDecodeError\u001b[0m                        Traceback (most recent call last)",
      "\u001b[1;31mUnicodeDecodeError\u001b[0m: 'utf-8' codec can't decode byte 0xe3 in position 76: invalid continuation byte"
     ]
    },
    {
     "name": "stderr",
     "output_type": "stream",
     "text": [
      "Exception ignored in: 'fiona._env.log_error'\n",
      "Traceback (most recent call last):\n",
      "  File \"D:\\Programas\\anaconda3\\envs\\gps_project\\lib\\site-packages\\fiona\\env.py\", line 289, in defenv\n",
      "    local._env.start()\n",
      "UnicodeDecodeError: 'utf-8' codec can't decode byte 0xe3 in position 76: invalid continuation byte\n"
     ]
    },
    {
     "ename": "UnicodeDecodeError",
     "evalue": "'utf-8' codec can't decode byte 0xe3 in position 76: invalid continuation byte",
     "output_type": "error",
     "traceback": [
      "\u001b[1;31m---------------------------------------------------------------------------\u001b[0m",
      "\u001b[1;31mUnicodeDecodeError\u001b[0m                        Traceback (most recent call last)",
      "\u001b[1;31mUnicodeDecodeError\u001b[0m: 'utf-8' codec can't decode byte 0xe3 in position 76: invalid continuation byte"
     ]
    },
    {
     "name": "stderr",
     "output_type": "stream",
     "text": [
      "Exception ignored in: 'fiona._env.log_error'\n",
      "Traceback (most recent call last):\n",
      "  File \"D:\\Programas\\anaconda3\\envs\\gps_project\\lib\\site-packages\\fiona\\env.py\", line 289, in defenv\n",
      "    local._env.start()\n",
      "UnicodeDecodeError: 'utf-8' codec can't decode byte 0xe3 in position 76: invalid continuation byte\n"
     ]
    },
    {
     "ename": "UnicodeDecodeError",
     "evalue": "'utf-8' codec can't decode byte 0xe3 in position 81: invalid continuation byte",
     "output_type": "error",
     "traceback": [
      "\u001b[1;31m---------------------------------------------------------------------------\u001b[0m",
      "\u001b[1;31mUnicodeDecodeError\u001b[0m                        Traceback (most recent call last)",
      "\u001b[1;31mUnicodeDecodeError\u001b[0m: 'utf-8' codec can't decode byte 0xe3 in position 81: invalid continuation byte"
     ]
    },
    {
     "name": "stderr",
     "output_type": "stream",
     "text": [
      "Exception ignored in: 'fiona._env.log_error'\n",
      "Traceback (most recent call last):\n",
      "  File \"D:\\Programas\\anaconda3\\envs\\gps_project\\lib\\site-packages\\fiona\\env.py\", line 289, in defenv\n",
      "    local._env.start()\n",
      "UnicodeDecodeError: 'utf-8' codec can't decode byte 0xe3 in position 81: invalid continuation byte\n"
     ]
    },
    {
     "ename": "UnicodeDecodeError",
     "evalue": "'utf-8' codec can't decode byte 0xe3 in position 81: invalid continuation byte",
     "output_type": "error",
     "traceback": [
      "\u001b[1;31m---------------------------------------------------------------------------\u001b[0m",
      "\u001b[1;31mUnicodeDecodeError\u001b[0m                        Traceback (most recent call last)",
      "\u001b[1;31mUnicodeDecodeError\u001b[0m: 'utf-8' codec can't decode byte 0xe3 in position 81: invalid continuation byte"
     ]
    },
    {
     "name": "stderr",
     "output_type": "stream",
     "text": [
      "Exception ignored in: 'fiona._env.log_error'\n",
      "Traceback (most recent call last):\n",
      "  File \"D:\\Programas\\anaconda3\\envs\\gps_project\\lib\\site-packages\\fiona\\env.py\", line 289, in defenv\n",
      "    local._env.start()\n",
      "UnicodeDecodeError: 'utf-8' codec can't decode byte 0xe3 in position 81: invalid continuation byte\n"
     ]
    },
    {
     "ename": "UnicodeDecodeError",
     "evalue": "'utf-8' codec can't decode byte 0xe3 in position 72: invalid continuation byte",
     "output_type": "error",
     "traceback": [
      "\u001b[1;31m---------------------------------------------------------------------------\u001b[0m",
      "\u001b[1;31mUnicodeDecodeError\u001b[0m                        Traceback (most recent call last)",
      "\u001b[1;31mUnicodeDecodeError\u001b[0m: 'utf-8' codec can't decode byte 0xe3 in position 72: invalid continuation byte"
     ]
    },
    {
     "name": "stderr",
     "output_type": "stream",
     "text": [
      "Exception ignored in: 'fiona._env.log_error'\n",
      "Traceback (most recent call last):\n",
      "  File \"D:\\Programas\\anaconda3\\envs\\gps_project\\lib\\site-packages\\fiona\\env.py\", line 289, in defenv\n",
      "    local._env.start()\n",
      "UnicodeDecodeError: 'utf-8' codec can't decode byte 0xe3 in position 72: invalid continuation byte\n"
     ]
    },
    {
     "ename": "UnicodeDecodeError",
     "evalue": "'utf-8' codec can't decode byte 0xe3 in position 72: invalid continuation byte",
     "output_type": "error",
     "traceback": [
      "\u001b[1;31m---------------------------------------------------------------------------\u001b[0m",
      "\u001b[1;31mUnicodeDecodeError\u001b[0m                        Traceback (most recent call last)",
      "\u001b[1;31mUnicodeDecodeError\u001b[0m: 'utf-8' codec can't decode byte 0xe3 in position 72: invalid continuation byte"
     ]
    },
    {
     "name": "stderr",
     "output_type": "stream",
     "text": [
      "Exception ignored in: 'fiona._env.log_error'\n",
      "Traceback (most recent call last):\n",
      "  File \"D:\\Programas\\anaconda3\\envs\\gps_project\\lib\\site-packages\\fiona\\env.py\", line 289, in defenv\n",
      "    local._env.start()\n",
      "UnicodeDecodeError: 'utf-8' codec can't decode byte 0xe3 in position 72: invalid continuation byte\n"
     ]
    },
    {
     "ename": "UnicodeDecodeError",
     "evalue": "'utf-8' codec can't decode byte 0xe3 in position 71: invalid continuation byte",
     "output_type": "error",
     "traceback": [
      "\u001b[1;31m---------------------------------------------------------------------------\u001b[0m",
      "\u001b[1;31mUnicodeDecodeError\u001b[0m                        Traceback (most recent call last)",
      "\u001b[1;31mUnicodeDecodeError\u001b[0m: 'utf-8' codec can't decode byte 0xe3 in position 71: invalid continuation byte"
     ]
    },
    {
     "name": "stderr",
     "output_type": "stream",
     "text": [
      "Exception ignored in: 'fiona._env.log_error'\n",
      "Traceback (most recent call last):\n",
      "  File \"D:\\Programas\\anaconda3\\envs\\gps_project\\lib\\site-packages\\fiona\\env.py\", line 289, in defenv\n",
      "    local._env.start()\n",
      "UnicodeDecodeError: 'utf-8' codec can't decode byte 0xe3 in position 71: invalid continuation byte\n"
     ]
    },
    {
     "ename": "UnicodeDecodeError",
     "evalue": "'utf-8' codec can't decode byte 0xe3 in position 71: invalid continuation byte",
     "output_type": "error",
     "traceback": [
      "\u001b[1;31m---------------------------------------------------------------------------\u001b[0m",
      "\u001b[1;31mUnicodeDecodeError\u001b[0m                        Traceback (most recent call last)",
      "\u001b[1;31mUnicodeDecodeError\u001b[0m: 'utf-8' codec can't decode byte 0xe3 in position 71: invalid continuation byte"
     ]
    },
    {
     "name": "stderr",
     "output_type": "stream",
     "text": [
      "Exception ignored in: 'fiona._env.log_error'\n",
      "Traceback (most recent call last):\n",
      "  File \"D:\\Programas\\anaconda3\\envs\\gps_project\\lib\\site-packages\\fiona\\env.py\", line 289, in defenv\n",
      "    local._env.start()\n",
      "UnicodeDecodeError: 'utf-8' codec can't decode byte 0xe3 in position 71: invalid continuation byte\n"
     ]
    },
    {
     "ename": "UnicodeDecodeError",
     "evalue": "'utf-8' codec can't decode byte 0xe3 in position 76: invalid continuation byte",
     "output_type": "error",
     "traceback": [
      "\u001b[1;31m---------------------------------------------------------------------------\u001b[0m",
      "\u001b[1;31mUnicodeDecodeError\u001b[0m                        Traceback (most recent call last)",
      "\u001b[1;31mUnicodeDecodeError\u001b[0m: 'utf-8' codec can't decode byte 0xe3 in position 76: invalid continuation byte"
     ]
    },
    {
     "name": "stderr",
     "output_type": "stream",
     "text": [
      "Exception ignored in: 'fiona._env.log_error'\n",
      "Traceback (most recent call last):\n",
      "  File \"D:\\Programas\\anaconda3\\envs\\gps_project\\lib\\site-packages\\fiona\\env.py\", line 289, in defenv\n",
      "    local._env.start()\n",
      "UnicodeDecodeError: 'utf-8' codec can't decode byte 0xe3 in position 76: invalid continuation byte\n"
     ]
    },
    {
     "ename": "UnicodeDecodeError",
     "evalue": "'utf-8' codec can't decode byte 0xe3 in position 76: invalid continuation byte",
     "output_type": "error",
     "traceback": [
      "\u001b[1;31m---------------------------------------------------------------------------\u001b[0m",
      "\u001b[1;31mUnicodeDecodeError\u001b[0m                        Traceback (most recent call last)",
      "\u001b[1;31mUnicodeDecodeError\u001b[0m: 'utf-8' codec can't decode byte 0xe3 in position 76: invalid continuation byte"
     ]
    },
    {
     "name": "stderr",
     "output_type": "stream",
     "text": [
      "Exception ignored in: 'fiona._env.log_error'\n",
      "Traceback (most recent call last):\n",
      "  File \"D:\\Programas\\anaconda3\\envs\\gps_project\\lib\\site-packages\\fiona\\env.py\", line 289, in defenv\n",
      "    local._env.start()\n",
      "UnicodeDecodeError: 'utf-8' codec can't decode byte 0xe3 in position 76: invalid continuation byte\n"
     ]
    },
    {
     "ename": "UnicodeDecodeError",
     "evalue": "'utf-8' codec can't decode byte 0xe3 in position 81: invalid continuation byte",
     "output_type": "error",
     "traceback": [
      "\u001b[1;31m---------------------------------------------------------------------------\u001b[0m",
      "\u001b[1;31mUnicodeDecodeError\u001b[0m                        Traceback (most recent call last)",
      "\u001b[1;31mUnicodeDecodeError\u001b[0m: 'utf-8' codec can't decode byte 0xe3 in position 81: invalid continuation byte"
     ]
    },
    {
     "name": "stderr",
     "output_type": "stream",
     "text": [
      "Exception ignored in: 'fiona._env.log_error'\n",
      "Traceback (most recent call last):\n",
      "  File \"D:\\Programas\\anaconda3\\envs\\gps_project\\lib\\site-packages\\fiona\\env.py\", line 289, in defenv\n",
      "    local._env.start()\n",
      "UnicodeDecodeError: 'utf-8' codec can't decode byte 0xe3 in position 81: invalid continuation byte\n"
     ]
    },
    {
     "ename": "UnicodeDecodeError",
     "evalue": "'utf-8' codec can't decode byte 0xe3 in position 81: invalid continuation byte",
     "output_type": "error",
     "traceback": [
      "\u001b[1;31m---------------------------------------------------------------------------\u001b[0m",
      "\u001b[1;31mUnicodeDecodeError\u001b[0m                        Traceback (most recent call last)",
      "\u001b[1;31mUnicodeDecodeError\u001b[0m: 'utf-8' codec can't decode byte 0xe3 in position 81: invalid continuation byte"
     ]
    },
    {
     "name": "stderr",
     "output_type": "stream",
     "text": [
      "Exception ignored in: 'fiona._env.log_error'\n",
      "Traceback (most recent call last):\n",
      "  File \"D:\\Programas\\anaconda3\\envs\\gps_project\\lib\\site-packages\\fiona\\env.py\", line 289, in defenv\n",
      "    local._env.start()\n",
      "UnicodeDecodeError: 'utf-8' codec can't decode byte 0xe3 in position 81: invalid continuation byte\n"
     ]
    },
    {
     "ename": "UnicodeDecodeError",
     "evalue": "'utf-8' codec can't decode byte 0xe3 in position 72: invalid continuation byte",
     "output_type": "error",
     "traceback": [
      "\u001b[1;31m---------------------------------------------------------------------------\u001b[0m",
      "\u001b[1;31mUnicodeDecodeError\u001b[0m                        Traceback (most recent call last)",
      "\u001b[1;31mUnicodeDecodeError\u001b[0m: 'utf-8' codec can't decode byte 0xe3 in position 72: invalid continuation byte"
     ]
    },
    {
     "name": "stderr",
     "output_type": "stream",
     "text": [
      "Exception ignored in: 'fiona._env.log_error'\n",
      "Traceback (most recent call last):\n",
      "  File \"D:\\Programas\\anaconda3\\envs\\gps_project\\lib\\site-packages\\fiona\\env.py\", line 289, in defenv\n",
      "    local._env.start()\n",
      "UnicodeDecodeError: 'utf-8' codec can't decode byte 0xe3 in position 72: invalid continuation byte\n"
     ]
    },
    {
     "ename": "UnicodeDecodeError",
     "evalue": "'utf-8' codec can't decode byte 0xe3 in position 72: invalid continuation byte",
     "output_type": "error",
     "traceback": [
      "\u001b[1;31m---------------------------------------------------------------------------\u001b[0m",
      "\u001b[1;31mUnicodeDecodeError\u001b[0m                        Traceback (most recent call last)",
      "\u001b[1;31mUnicodeDecodeError\u001b[0m: 'utf-8' codec can't decode byte 0xe3 in position 72: invalid continuation byte"
     ]
    },
    {
     "name": "stderr",
     "output_type": "stream",
     "text": [
      "Exception ignored in: 'fiona._env.log_error'\n",
      "Traceback (most recent call last):\n",
      "  File \"D:\\Programas\\anaconda3\\envs\\gps_project\\lib\\site-packages\\fiona\\env.py\", line 289, in defenv\n",
      "    local._env.start()\n",
      "UnicodeDecodeError: 'utf-8' codec can't decode byte 0xe3 in position 72: invalid continuation byte\n"
     ]
    },
    {
     "ename": "UnicodeDecodeError",
     "evalue": "'utf-8' codec can't decode byte 0xe3 in position 71: invalid continuation byte",
     "output_type": "error",
     "traceback": [
      "\u001b[1;31m---------------------------------------------------------------------------\u001b[0m",
      "\u001b[1;31mUnicodeDecodeError\u001b[0m                        Traceback (most recent call last)",
      "\u001b[1;31mUnicodeDecodeError\u001b[0m: 'utf-8' codec can't decode byte 0xe3 in position 71: invalid continuation byte"
     ]
    },
    {
     "name": "stderr",
     "output_type": "stream",
     "text": [
      "Exception ignored in: 'fiona._env.log_error'\n",
      "Traceback (most recent call last):\n",
      "  File \"D:\\Programas\\anaconda3\\envs\\gps_project\\lib\\site-packages\\fiona\\env.py\", line 289, in defenv\n",
      "    local._env.start()\n",
      "UnicodeDecodeError: 'utf-8' codec can't decode byte 0xe3 in position 71: invalid continuation byte\n"
     ]
    },
    {
     "ename": "UnicodeDecodeError",
     "evalue": "'utf-8' codec can't decode byte 0xe3 in position 71: invalid continuation byte",
     "output_type": "error",
     "traceback": [
      "\u001b[1;31m---------------------------------------------------------------------------\u001b[0m",
      "\u001b[1;31mUnicodeDecodeError\u001b[0m                        Traceback (most recent call last)",
      "\u001b[1;31mUnicodeDecodeError\u001b[0m: 'utf-8' codec can't decode byte 0xe3 in position 71: invalid continuation byte"
     ]
    },
    {
     "name": "stderr",
     "output_type": "stream",
     "text": [
      "Exception ignored in: 'fiona._env.log_error'\n",
      "Traceback (most recent call last):\n",
      "  File \"D:\\Programas\\anaconda3\\envs\\gps_project\\lib\\site-packages\\fiona\\env.py\", line 289, in defenv\n",
      "    local._env.start()\n",
      "UnicodeDecodeError: 'utf-8' codec can't decode byte 0xe3 in position 71: invalid continuation byte\n"
     ]
    }
   ],
   "source": [
    "import geopandas\n",
    "input_shape = \"https://opendata.arcgis.com/datasets/045b1d5147634e2380566668e04094c6_3.geojson\"\n",
    "gdf = geopandas.read_file(input_shape)"
   ]
  }
 ],
 "metadata": {
  "interpreter": {
   "hash": "4dce84d1d0b0a2614014f50ddc754a85fcae7539a149decca85d87d7385cd97c"
  },
  "kernelspec": {
   "display_name": "Python 3.10.2 ('gps_project')",
   "language": "python",
   "name": "python3"
  },
  "language_info": {
   "codemirror_mode": {
    "name": "ipython",
    "version": 3
   },
   "file_extension": ".py",
   "mimetype": "text/x-python",
   "name": "python",
   "nbconvert_exporter": "python",
   "pygments_lexer": "ipython3",
   "version": "3.10.2"
  },
  "orig_nbformat": 4
 },
 "nbformat": 4,
 "nbformat_minor": 2
}
